2018-04-04 00:34:00,544 - file_process.py[line:25] - INFO: save_path/var/www/Cono/media/image/crop/56_thumbnail.jpg
2018-04-04 00:34:00,544 - file_process.py[line:26] - INFO: a
2018-04-04 00:34:00,545 - file_process.py[line:27] - INFO: infile/var/www/Cono/media/推文图片/2018/04/03/u9158911681838345579fm27gp0_QwijF43.jpg
2018-04-04 00:34:00,548 - exception.py[line:118] - ERROR: Internal Server Error: /api/upload/commit
Traceback (most recent call last):
  File "/root/.envs/django/lib/python3.6/site-packages/django/core/handlers/exception.py", line 35, in inner
    response = get_response(request)
  File "/root/.envs/django/lib/python3.6/site-packages/django/core/handlers/base.py", line 128, in _get_response
    response = self.process_exception_by_middleware(e, request)
  File "/root/.envs/django/lib/python3.6/site-packages/django/core/handlers/base.py", line 126, in _get_response
    response = wrapped_callback(request, *callback_args, **callback_kwargs)
  File "/root/.envs/django/lib/python3.6/site-packages/django/views/decorators/csrf.py", line 54, in wrapped_view
    return view_func(*args, **kwargs)
  File "./apps/medium/views.py", line 131, in pub_commit_view
    tweet.save_with_thumbnail()
  File "./apps/tweet/models.py", line 48, in save_with_thumbnail
    thumbnail_path = self.image_obj_scale_handle(first_image)
  File "./apps/tweet/models.py", line 58, in image_obj_scale_handle
    scaled_image_path = image_scale(IMAGE_THUMBNAIL_SIZE, img_path,thumb_save_path)
  File "./util/file_process.py", line 44, in image_scale
    region.save(save_path)
  File "/root/.envs/django/lib/python3.6/site-packages/PIL/Image.py", line 1925, in save
    fp = builtins.open(filename, "w+b")
FileNotFoundError: [Errno 2] No such file or directory: '/var/www/Cono/media/image/crop/56_thumbnail.jpg'
2018-04-04 00:37:31,083 - exception.py[line:118] - ERROR: Internal Server Error: /api/upload/commit
Traceback (most recent call last):
  File "/root/.envs/django/lib/python3.6/site-packages/django/db/backends/utils.py", line 85, in _execute
    return self.cursor.execute(sql, params)
  File "/root/.envs/django/lib/python3.6/site-packages/django/db/backends/mysql/base.py", line 71, in execute
    return self.cursor.execute(query, args)
  File "/root/.envs/django/lib/python3.6/site-packages/MySQLdb/cursors.py", line 250, in execute
    self.errorhandler(self, exc, value)
  File "/root/.envs/django/lib/python3.6/site-packages/MySQLdb/connections.py", line 50, in defaulterrorhandler
    raise errorvalue
  File "/root/.envs/django/lib/python3.6/site-packages/MySQLdb/cursors.py", line 247, in execute
    res = self._query(query)
  File "/root/.envs/django/lib/python3.6/site-packages/MySQLdb/cursors.py", line 411, in _query
    rowcount = self._do_query(q)
  File "/root/.envs/django/lib/python3.6/site-packages/MySQLdb/cursors.py", line 374, in _do_query
    db.query(q)
  File "/root/.envs/django/lib/python3.6/site-packages/MySQLdb/connections.py", line 277, in query
    _mysql.connection.query(self, query)
_mysql_exceptions.IntegrityError: (1062, "Duplicate entry '56' for key 'short_code'")

The above exception was the direct cause of the following exception:

Traceback (most recent call last):
  File "/root/.envs/django/lib/python3.6/site-packages/django/core/handlers/exception.py", line 35, in inner
    response = get_response(request)
  File "/root/.envs/django/lib/python3.6/site-packages/django/core/handlers/base.py", line 128, in _get_response
    response = self.process_exception_by_middleware(e, request)
  File "/root/.envs/django/lib/python3.6/site-packages/django/core/handlers/base.py", line 126, in _get_response
    response = wrapped_callback(request, *callback_args, **callback_kwargs)
  File "/root/.envs/django/lib/python3.6/site-packages/django/views/decorators/csrf.py", line 54, in wrapped_view
    return view_func(*args, **kwargs)
  File "./apps/medium/views.py", line 119, in pub_commit_view
    tweet = Tweet.objects.create(**tweet_data)
  File "/root/.envs/django/lib/python3.6/site-packages/django/db/models/manager.py", line 82, in manager_method
    return getattr(self.get_queryset(), name)(*args, **kwargs)
  File "/root/.envs/django/lib/python3.6/site-packages/django/db/models/query.py", line 417, in create
    obj.save(force_insert=True, using=self.db)
  File "/root/.envs/django/lib/python3.6/site-packages/django/db/models/base.py", line 729, in save
    force_update=force_update, update_fields=update_fields)
  File "/root/.envs/django/lib/python3.6/site-packages/django/db/models/base.py", line 759, in save_base
    updated = self._save_table(raw, cls, force_insert, force_update, using, update_fields)
  File "/root/.envs/django/lib/python3.6/site-packages/django/db/models/base.py", line 842, in _save_table
    result = self._do_insert(cls._base_manager, using, fields, update_pk, raw)
  File "/root/.envs/django/lib/python3.6/site-packages/django/db/models/base.py", line 880, in _do_insert
    using=using, raw=raw)
  File "/root/.envs/django/lib/python3.6/site-packages/django/db/models/manager.py", line 82, in manager_method
    return getattr(self.get_queryset(), name)(*args, **kwargs)
  File "/root/.envs/django/lib/python3.6/site-packages/django/db/models/query.py", line 1125, in _insert
    return query.get_compiler(using=using).execute_sql(return_id)
  File "/root/.envs/django/lib/python3.6/site-packages/django/db/models/sql/compiler.py", line 1280, in execute_sql
    cursor.execute(sql, params)
  File "/root/.envs/django/lib/python3.6/site-packages/django/db/backends/utils.py", line 100, in execute
    return super().execute(sql, params)
  File "/root/.envs/django/lib/python3.6/site-packages/django/db/backends/utils.py", line 68, in execute
    return self._execute_with_wrappers(sql, params, many=False, executor=self._execute)
  File "/root/.envs/django/lib/python3.6/site-packages/django/db/backends/utils.py", line 77, in _execute_with_wrappers
    return executor(sql, params, many, context)
  File "/root/.envs/django/lib/python3.6/site-packages/django/db/backends/utils.py", line 85, in _execute
    return self.cursor.execute(sql, params)
  File "/root/.envs/django/lib/python3.6/site-packages/django/db/utils.py", line 89, in __exit__
    raise dj_exc_value.with_traceback(traceback) from exc_value
  File "/root/.envs/django/lib/python3.6/site-packages/django/db/backends/utils.py", line 85, in _execute
    return self.cursor.execute(sql, params)
  File "/root/.envs/django/lib/python3.6/site-packages/django/db/backends/mysql/base.py", line 71, in execute
    return self.cursor.execute(query, args)
  File "/root/.envs/django/lib/python3.6/site-packages/MySQLdb/cursors.py", line 250, in execute
    self.errorhandler(self, exc, value)
  File "/root/.envs/django/lib/python3.6/site-packages/MySQLdb/connections.py", line 50, in defaulterrorhandler
    raise errorvalue
  File "/root/.envs/django/lib/python3.6/site-packages/MySQLdb/cursors.py", line 247, in execute
    res = self._query(query)
  File "/root/.envs/django/lib/python3.6/site-packages/MySQLdb/cursors.py", line 411, in _query
    rowcount = self._do_query(q)
  File "/root/.envs/django/lib/python3.6/site-packages/MySQLdb/cursors.py", line 374, in _do_query
    db.query(q)
  File "/root/.envs/django/lib/python3.6/site-packages/MySQLdb/connections.py", line 277, in query
    _mysql.connection.query(self, query)
django.db.utils.IntegrityError: (1062, "Duplicate entry '56' for key 'short_code'")
2018-04-04 00:37:43,902 - file_process.py[line:25] - INFO: save_path/var/www/Cono/media/image/crop/57_thumbnail.jpg
2018-04-04 00:37:43,902 - file_process.py[line:26] - INFO: a
2018-04-04 00:37:43,902 - file_process.py[line:27] - INFO: infile/var/www/Cono/media/推文图片/2018/04/03/u9158911681838345579fm27gp0_3jjcjU0.jpg
2018-04-04 00:37:43,908 - file_process.py[line:45] - INFO: saved
2018-04-04 00:40:51,661 - file_process.py[line:25] - INFO: save_path/var/www/Cono/media/image/crop/58_thumbnail.jpg
2018-04-04 00:40:51,661 - file_process.py[line:26] - INFO: a
2018-04-04 00:40:51,661 - file_process.py[line:27] - INFO: infile/var/www/Cono/media/推文图片/2018/04/03/u9158911681838345579fm27gp0_sgucfsw.jpg
2018-04-04 00:40:51,667 - file_process.py[line:45] - INFO: saved
